Workbook
Name _______________________xlnm.Print_Area_7: #REF!
Name ______________________xlnm.Print_Area_7: #REF!
Name ______________________xlnm.Print_Area_7: #REF!
Name ______________________xlnm.Print_Area_7: #REF!
Name _____________________xlnm.Print_Area_7: #REF!
Name _____________________xlnm.Print_Area_7: #REF!
Name _____________________xlnm.Print_Area_7: #REF!
Name ____________________xlnm.Print_Area_7: #REF!
Name ____________________xlnm.Print_Area_7: #REF!
Name ____________________xlnm.Print_Area_7: #REF!
Name ___________________xlnm.Print_Area_7: #REF!
Name ___________________xlnm.Print_Area_7: #REF!
Name ___________________xlnm.Print_Area_7: #REF!
Name __________________xlnm.Print_Area_7: #REF!
Name __________________xlnm.Print_Area_7: #REF!
Name __________________xlnm.Print_Area_7: #REF!
Name __________________xlnm.Print_Area_7: #REF!
Name __________________xlnm.Print_Area_7: #REF!
Name _________________xlnm.Print_Area_7: #REF!
Name _________________xlnm.Print_Area_7: #REF!
Name _________________xlnm.Print_Area_7: #REF!
Name _________________xlnm.Print_Area_7: #REF!
Name _________________xlnm.Print_Area_7: #REF!
Name ________________xlnm.Print_Area_7: #REF!
Name ________________xlnm.Print_Area_7: #REF!
Name _______________xlnm.Print_Area_7: #REF!
Name _______________xlnm.Print_Area_7: #REF!
Name _______________xlnm.Print_Area_7: #REF!
Name _______________xlnm.Print_Area_7: #REF!
Name ______________xlnm.Print_Area_7: #REF!
Name ______________xlnm.Print_Area_7: #REF!
Name ______________xlnm.Print_Area_7: #REF!
Name ______________xlnm.Print_Area_7: #REF!
Name ______________xlnm.Print_Area_7: #REF!
Name _____________xlnm.Print_Area_7: #REF!
Name _____________xlnm.Print_Area_7: #REF!
Name _____________xlnm.Print_Area_7: #REF!
Name _____________xlnm.Print_Area_7: #REF!
Name _____________xlnm.Print_Area_7: #REF!
Name ____________xlnm.Print_Area_7: #REF!
Name ____________xlnm.Print_Area_7: #REF!
Name ____________xlnm.Print_Area_7: #REF!
Name ____________xlnm.Print_Area_7: #REF!
Name ___________xlnm.Print_Area_7: #REF!
Name ___________xlnm.Print_Area_7: #REF!
Name ___________xlnm.Print_Area_7: #REF!
Name ___________xlnm.Print_Area_7: #REF!
Name __________xlnm.Print_Area_7: #REF!
Name __________xlnm.Print_Area_7: #REF!
Name __________xlnm.Print_Area_7: #REF!
Name __________xlnm.Print_Area_7: #REF!
Name _________xlnm.Print_Area_7: #REF!
Name _________xlnm.Print_Area_7: #REF!
Name _________xlnm.Print_Area_7: #REF!
Name _________xlnm.Print_Area_7: #REF!
Name _________xlnm.Print_Area_7: #REF!
Name ________xlnm.Print_Area_7: #REF!
Name ________xlnm.Print_Area_7: #REF!
Name ________xlnm.Print_Area_7: #REF!
Name ________xlnm.Print_Area_7: #REF!

Sheet Covering Letter 
F4: Jakarta, 10 Februari 2025
B5: No. | C5: : | D5: CS/0001/2025
B6: Perihal | C6: : | D6: Penawaran Harga Jasa Job Supply Maintenance
B7: Lampiran | C7: : | D7: 7 Lembar
B9: Kepada Yth;
B10: PT United Tractors Tbk
B11: Jl. Raya Bekasi KM 22
B12: Kec. Cakung, Kota Jakarta Timur
B13: Daerah Khusus Ibukota Jakarta 13910
B15: Up | C15: : | D15: Ibu Sara Kirsti Loebis
D16: Corporate Governance & Sustainability Division Head
B19: Dengan hormat,
B20: Sehubungan dengan adanya kebutuhan Penyedia Jasa Tenaga Kerja di perusahaan Bapak/Ibu, bersama ini kami sampaikan penawaran dari PT Mitra Bakti UT sebagai berikut:
B22: - Penyedia Jasa Tenaga Kerja (rincian terlampir)
B23: Rp | D23: =RECAP!E19 -> 561637600
B25: Note :
B26: 1. Harga belum termasuk PPN 11%
B27: 2. Lingkup pekerjaan & Tools terlampir dalam proposal ini
B28: 3. Harga tersebut sudah termasuk BPJS Kesehatan, BPJS Ketenagakerjaan (BPJS Jaminan Kecelakaan Kerja,
B29: BPJS Jaminan Kematian, BPJS Jaminan Hari Tua, BPJS Jaminan Pensiun), Kompensasi Kerja (PP no 35
B30: Tahun 2021), Tunjangan Hari Raya (THR), Alat Pelindung Diri (APD) dan Pakaian Kerja
B31: 4. Harga sudah termasuk biaya MCU, kelebihan biaya MCU ditagihkan sesuai aktual dengan Management Fee 5%
B32: 5. Perhitungan dan aturan lembur sesuai aturan disnaker
B33: 6. Lembur ditagihkan sesuai aktual dengan management fee 5%
B34: 7. Makan disediakan oleh User
B35: 8. Sertifikasi akan dilakukan oleh User
B36: 9. Training ditagihkan sesuai aktual dengan management fee 5%
... B49: Strategic Business & Sales Division Head

Sheet RECAP
K3: 89669600
B4: Lampiran 1 | K4: =E13-K3 -> -767357.14
B5: No. | C5: ='Covering Letter '!D5 -> CS/0001/2025
B7: BIAYA JASA JOB SUPPLY MAINTENANCE BUILDING TAHUN 2025
B8: NAMA | E8: : PT MITRA BAKTI UT
B9: AREA PELAYANAN | E9: : PT UNITED TRACTORS TBK
R10: MP | T10: VENDOR | U10: TOOLS | V10: SUB TOTAL
B11: 1 | C11: MECHANICAL ELECTRICAL | E11: =V11 -> 1.2348654e+08 | R11: ='SC MP'!F42+'SC MP'!G42 -> 108061400 | S11: =('SC MP'!L42+'SC MP'!M42)*(13/28) -> 8062600 | T11: 0 | U11: =TOOLS!J21+TOOLS!I83 -> 7362538.6 | V11: =SUM(R11:U11) -> 1.2348654e+08
B12: 2 | C12: MAINTENANCE AC | E12: =V12 -> 1.1935622e+08 | R12: ='SC MP'!H42+'SC MP'!I42 -> 99913600 | S12: =('SC MP'!L42+'SC MP'!M42)*(12/28) -> 7442400 | T12: 0 | U12: =TOOLS!J21+TOOLS!I143 -> 12000219 | V12: =SUM(R12:U12) -> 1.1935622e+08
B13: 3 | C13: IPAL | E13: =V13 -> 88902243 | K13: =E13*12 -> 1.0668269e+09 | R13: ='SC MP'!J42+'SC MP'!K42 -> 25513400 | S13: =('SC MP'!L42+'SC MP'!M42)*(3/28) -> 1860600 | T13: =VENDOR!I6 -> 60509232 | U13: =TOOLS!J21 -> 1019010.5 | V13: =SUM(R13:U13) -> 88902243
B14: 4 | C14: ME & CIVIL PPI CAKUNG | E14: =V14 -> 1.0314786e+08 | R14: ='SC MP'!N42+'SC MP'!O42 -> 99913600 | S14: 0 | T14: =('SC MP'!M44+'SC MP'!N44)*(13/28) -> 0 | U14: =TOOLS!J21+TOOLS!I161 -> 3234261.1 | V14: =SUM(R14:U14) -> 1.0314786e+08
B15: 5 | C15: CIVIL REPAIR MAINTENANCE | E15: =V15 -> 100000000 | R15: ='SC MP'!F46+'SC MP'!G46 -> 0 | S15: 0 | T15: 100000000 | U15: =('SC MP'!N45+'SC MP'!O45)*(13/28) -> 0 | V15: =SUM(R15:U15) -> 100000000
B16: SUB TOTAL | E16: =SUM(E11:H15) -> 5.3489286e+08 | R16: =SUM(R11:S15) -> 350767600 | T16: =SUM(T11:T15) -> 1.6050923e+08 | U16: =SUM(U11:U15) -> 23616030 | V16: =SUM(V11:V15) -> 5.3489286e+08
B17: MANAGEMENT FEE 5% | E17: =E16*5% -> 26744643 | R17: 26744643
B18: GRAND TOTAL | E18: =E16+E17 -> 5.6163751e+08
B19: PEMBULATAN | E19: =ROUNDUP(E18,-2) -> 561637600
B21: SCOPE OF JOB | L21: HARGA 2024 | M21: HARGA 2025 | N21: DEVIASI | O21: %
B22: No | C22: Equipment | D22: Item Check | E22: Jumlah | F22: Satuan | G22: Biaya Per Bulan | H22: Biaya Per Tahun | L22: 908003000 | M22: =E19 -> 561637600 | N22: =M22-L22 -> -346365400 | O22: =N22/L22 -> -0.38145843
B23: 1 | C23: =C11 -> MECHANICAL ELECTRICAL
B24: a | C24: Genset | L24: Simulasi + Lembur | U24: 561637600
C25: Gedung UT New Building (UTNB) | D25: - Daily Check Inspection - Running Test | E25: 5 | F25: unit | G25: =E11 -> 1.2348654e+08 | H25: =G25*12 -> 1.4818385e+09 | L25: HARGA 2024 | M25: HARGA 2025 | N25: DEVIASI | O25: %
C26: Gedung Employee Center (EC) | E26: 1 | F26: unit | L26: 908003000 | M26: =M22 -> 561637600 | N26: =M28-L26 -> -2.4261794e+08 | O26: =N26/L26 -> -0.26719949
C27: Gedung ITC | E27: 1 | F27: unit | M27: =3167*'SC MP'!F20 -> 1.0374746e+08
C28: Gedung UT HO-B | E28: =4-1 -> 3 | F28: unit | M28: =SUM(M26:M27) -> 6.6538506e+08
C29: Gedung UT Corpu | E29: 1 | F29: unit
C30: Gedung KMSI | E30: 1 | F30: unit
C31: Area Masjid | E31: 1 | F31: unit
C32: Workshop UTPE (ex UTR) | E32: 1 | F32: unit
C33: Portable | E33: 1 | F33: unit
B34: b | C34: Hydrant
C35: Gedung UT New Building (UTNB) | D35: - Daily Check Inspection - Running Test | E35: 3 | F35: unit
C36: Gedung Employee Center (EC) | E36: 3 | F36: unit
C37: Area Yard Marketing | E37: 3 | F37: unit
C38: Gedung UT Corpu | E38: 3 | F38: unit
C39: Area UT Jababeka | E39: 3 | F39: unit
B40: c | C40: Pump
C41: Gedung UT New Building (UTNB) | D41: - Daily Check Inspection - Monthly Check | E41: 31 | F41: unit
C42: Gedung Employee Center (EC) | E42: 9 | F42: unit
C43: Gedung UT School | E43: 2 | F43: unit
C44: Gedung UT Corpu | E44: 6 | F44: unit
...

Sheet SC MP
B5: Lampiran 1
B6: No. | C6: ='Covering Letter '!D5 -> CS/0001/2025
B8: STRUKTUR BIAYA JASA TENAGA KERJA
B9: TAHUN 2025
B10: AREA DKI JAKARTA
B12: NO | C12: URAIAN | F12: ME & TELECOMMUNICATION | H12: AC | J12: IPAL | L12: ALL | N12: TIM 10 | P12: KETERANGAN
F13: SUPERVISOR | G13: CREW | H13: SUPERVISOR | I13: CREW | J13: SUPERVISOR | K13: CREW | L13: KOORDINATOR | M13: ADMIN | N13: SUPERVISOR | O13: CREW
B14: I | C14: FIXED COST | F14: =SUM(F15:F18) -> 6849685.8 | G14: =SUM(G15:G18) -> 6849685.8 | H14: =SUM(H15:H18) -> 6849685.8 | I14: =SUM(I15:I18) -> 6849685.8 | J14: =SUM(J15:J18) -> 6849685.8 | K14: =SUM(K15:K18) -> 6849685.8 | L14: =SUM(L15:L18) -> 6849685.8 | M14: =SUM(M15:M18) -> 6849685.8 | ... O14: =SUM(O15:O18) -> 6849685.8 | Q14: 42
B15: 1 | C15: Upah | F15: =5068000*106.5% -> 5397420 | G15: =5068000*106.5% -> 5397420 | H15: =5068000*106.5% -> 5397420 | I15: =5068000*106.5% -> 5397420 | J15: =5068000*106.5% -> 5397420 | K15: =5068000*106.5% -> 5397420 | L15: =5068000*106.5% -> 5397420 | M15: =5068000*106.5% -> 5397420 | ... O15: =5068000*106.5% -> 5397420 | P15: Upah Tenaga Kerja (UMK 2025) | Q15: =F15*$Q$14 -> 226691640
B16: 2 | C16: BPJS | E16: 0.1024 | F16: 552695.81 | G16: 552695.81 | H16: 552695.81 | I16: 552695.81 | J16: 552695.81 | K16: 552695.81 | L16: 552695.81 | M16: 552695.81 | N16: =E16*N15 -> 552695.81 | O16: =E16*O15 -> 552695.81 | P16: Mengikuti Regulasi Pemerintah (JHT, JKK, JK) | Q16: =F16*$Q$14 -> 23213224
B17: 3 | C17: THR | F17: 449785 | G17: 449785 | H17: 449785 | I17: 449785 | J17: 449785 | K17: 449785 | L17: 449785 | M17: 449785 | N17: =N15/12 -> 449785 | O17: =O15/12 -> 449785 | P17: Upah /12 | Q17: =F17*$Q$14 -> 18890970
B18: 4 | C18: Kompensasi Akhir Kontrak (UUCK) | F18: 449785 | G18: 449785 | H18: 449785 | I18: 449785 | J18: 449785 | K18: 449785 | L18: 449785 | M18: 449785 | N18: =N15/12 -> 449785 | O18: =O15/12 -> 449785 | P18: Upah /12 | Q18: =F18*$Q$14 -> 18890970
B19: II | C19: OVERTIME | F19: =F22 -> 0 | G19: =G22 -> 0 | H19: =H22 -> 0 | I19: =I22 -> 0 | J19: =J22 -> 0 | K19: =K22 -> 0 | L19: =L22 -> 0 | M19: =M22 -> 0 | ... O19: =O22 -> 0 | Q19: =F19*$Q$14 -> 0
B20: 1 | C20: TUL | F20: =SUM(F15/173)*105% -> 32758.908 | G20: =SUM(G15/173)*105% -> 32758.908 | H20: =SUM(H15/173)*105% -> 32758.908 | I20: =SUM(I15/173)*105% -> 32758.908 | J20: =SUM(J15/173)*105% -> 32758.908 | K20: =SUM(K15/173)*105% -> 32758.908 | L20: =SUM(L15/173)*105% -> 32758.908 | M20: =SUM(M15/173)*105% -> 32758.908 | ... O20: =SUM(O15/173)*105% -> 32758.908 | P20: Upah /173 | Q20: =F20*$Q$14 -> 1375874.1
B21: 2 | C21: Jam Lembur | F21: 0 | G21: 0 | H21: 0 | I21: 0 | J21: 0 | K21: 0 | L21: 0 | M21: 0 | N21: 0 | O21: 0 | P21: Sesuai Aktual Dilapangan | Q21: =F21*$Q$14 -> 0
B22: 3 | C22: Upah Lembur | F22: =F20*F21 -> 0 | G22: =G20*G21 -> 0 | H22: =H20*H21 -> 0 | I22: =I20*I21 -> 0 | J22: =J20*J21 -> 0 | K22: =K20*K21 -> 0 | L22: =L20*L21 -> 0 | M22: =M20*M21 -> 0 | P22: Ditagihkan Sesuai Aktual Dengan Management Fee 5% | Q22: =F22*$Q$14 -> 0
B23: III | C23: VARIABLE COST | F23: =SUM(F24:F31) -> 1765000 | G23: =SUM(G24:G31) -> 765000 | H23: =SUM(H24:H31) -> 1765000 | I23: =SUM(I24:I31) -> 765000 | J23: =SUM(J24:J31) -> 1765000 | K23: =SUM(K24:K31) -> 765000 | L23: =SUM(L24:L31) -> 1765000 | M23: =SUM(M24:M31) -> 765000 | ... O23: =SUM(O24:O31) -> 765000 | Q23: =F23*$Q$14 -> 74130000
B24: 1 | C24: Medical Checkup | F24: 60000 | G24: 60000 | H24: 60000 | I24: 60000 | J24: 60000 | K24: 60000 | L24: 60000 | M24: 60000 | N24: 60000 | O24: 60000 | P24: Kelebihan biaya MCU ditagihkan sesuai aktual | Q24: =F24*$Q$14 -> 2520000
B25: 2 | C25: Seragam | F25: 135000 | G25: 135000 | H25: 135000 | I25: 135000 | J25: 135000 | K25: 135000 | L25: 135000 | M25: 135000 | N25: 135000 | O25: 135000 | P25: 3 Pasang Per Tahun (Baju, Kaos & Celana) | Q25: =F25*$Q$14 -> 5670000
B26: 3 | C26: APD | F26: 70000 | G26: 70000 | H26: 70000 | I26: 70000 | J26: 70000 | K26: 70000 | L26: 70000 | M26: 70000 | N26: 70000 | O26: 70000 | P26: Helm & sepatu safety | Q26: =F26*$Q$14 -> 2940000
B27: 4 | C27: Uang Makan | F27: 0 | G27: 0 | H27: 0 | I27: 0 | J27: 0 | K27: 0 | L27: 0 | M27: 0 | N27: 0 | O27: 0 | P27: Disediakan oleh User | Q27: =F27*$Q$14 -> 0
B28: 5 | C28: Sertifikasi | F28: 0 | G28: 0 | H28: 0 | I28: 0 | J28: 0 | K28: 0 | L28: 0 | M28: 0 | N28: 0 | O28: 0 | P28: Dilakukan oleh User | Q28: =F28*$Q$14 -> 0
B29: 6 | C29: Training | F29: 0 | G29: 0 | H29: 0 | I29: 0 | J29: 0 | K29: 0 | L29: 0 | M29: 0 | N29: 0 | O29: 0 | P29: Ditagihkan Sesuai Aktual Dengan Management Fee 5% | Q29: =F29*$Q$14 -> 0
B30: 7 | C30: Tunjangan Jabatan | F30: 1000000 | H30: 1000000 | J30: 1000000 | L30: 1000000 | N30: 1000000 | Q30: =F30*$Q$14 -> 42000000
B31: 8 | C31: Overhead Expenses | F31: =SUM(F32:F35) -> 500000 | G31: =SUM(G32:G35) -> 500000 | H31: =SUM(H32:H35) -> 500000 | I31: =SUM(I32:I35) -> 500000 | J31: =SUM(J32:J35) -> 500000 | K31: =SUM(K32:K35) -> 500000 | L31: =SUM(L32:L35) -> 500000 | M31: =SUM(M32:M35) -> 500000 | ... O31: =SUM(O32:O35) -> 500000 | Q31: =F31*$Q$14 -> 21000000
C32: Biaya Sambung Rasa | F32: 155000 | G32: 155000 | H32: 155000 | I32: 155000 | J32: 155000 | K32: 155000 | L32: 155000 | M32: 155000 | N32: 155000 | O32: 155000 | Q32: =F32*$Q$14 -> 6510000
C33: Biaya Recruitment | F33: 50000 | G33: 50000 | H33: 50000 | I33: 50000 | J33: 50000 | K33: 50000 | L33: 50000 | M33: 50000 | N33: 50000 | O33: 50000 | Q33: =F33*$Q$14 -> 2100000
C34: Biaya Suka Duka | F34: 45000 | G34: 45000 | H34: 45000 | I34: 45000 | J34: 45000 | K34: 45000 | L34: 45000 | M34: 45000 | N34: 45000 | O34: 45000 | Q34: =F34*$Q$14 -> 1890000
C35: Biaya Operational Support | F35: 250000 | G35: 250000 | H35: 250000 | I35: 250000 | J35: 250000 | K35: 250000 | L35: 250000 | M35: 250000 | N35: 250000 | O35: 250000 | Q35: =F35*$Q$14 -> 10500000
C36: TOTAL I + II + III | F36: =F14+F19+F23 -> 8614685.8 | G36: =G14+G19+G23 -> 7614685.8 | H36: =H14+H19+H23 -> 8614685.8 | I36: =I14+I19+I23 -> 7614685.8 | J36: =J14+J19+J23 -> 8614685.8 | K36: =K14+K19+K23 -> 7614685.8 | L36: =L14+L19+L23 -> 8614685.8 | M36: =M14+M19+M23 -> 7614685.8 | ... O36: =O14+O19+O23 -> 7614685.8 | Q36: =F36*$Q$14 -> 3.618168e+08
C37: MANAGEMENT FEE | E37: 0.07 | F37: =F36*$E$37 -> 603028.01 | G37: =G36*$E$37 -> 533028.01 | H37: =H36*$E$37 -> 603028.01 | I37: =I36*$E$37 -> 533028.01 | J37: =J36*$E$37 -> 603028.01 | K37: =K36*$E$37 -> 533028.01 | L37: =L36*$E$37 -> 603028.01 | M37: =M36*$E$37 -> 533028.01 | ... O37: =O36*$E$37 -> 533028.01 | Q37: =F37*$Q$14 -> 25327176
C38: SUB TOTAL | F38: =F36+F37 -> 9217713.8 | G38: =G36+G37 -> 8147713.8 | H38: =H36+H37 -> 9217713.8 | I38: =I36+I37 -> 8147713.8 | J38: =J36+J37 -> 9217713.8 | K38: =K36+K37 -> 8147713.8 | L38: =L36+L37 -> 9217713.8 | M38: =M36+M37 -> 8147713.8 | ... O38: =O36+O37 -> 8147713.8 | Q38: =F38*$Q$14 -> 3.8714398e+08
C39: PEMBULATAN | F39: =ROUNDUP(F38,-2) -> 9217800 | G39: =ROUNDUP(G38,-2) -> 8147800 | H39: =ROUNDUP(H38,-2) -> 9217800 | I39: =ROUNDUP(I38,-2) -> 8147800 | J39: =ROUNDUP(J38,-2) -> 9217800 | K39: =ROUNDUP(K38,-2) -> 8147800 | L39: =ROUNDUP(L38,-2) -> 9217800 | M39: =ROUNDUP(M38,-2) -> 8147800 | ... O39: =ROUNDUP(O38,-2) -> 8147800 | Q39: =F39*$Q$14 -> 387147600
C41: JUMLAH MANPOWER | F41: 2 | G41: 11 | H41: 2 | I41: 10 | J41: 1 | K41: 2 | L41: 1 | M41: 1 | N41: 2 | O41: 10 | P41: =SUM(F41:O41)-4 -> 38
C42: TOTAL BIAYA MANPOWER | F42: =F39*F41 -> 18435600 | G42: =G39*G41 -> 89625800 | H42: =H39*H41 -> 18435600 | I42: =I39*I41 -> 81478000 | J42: =J39*J41 -> 9217800 | K42: =K39*K41 -> 16295600 | L42: =L39*L41 -> 9217800 | M42: =M39*M41 -> 8147800 | ... O42: =O39*O41 -> 81478000 | P42: =SUM(F42:O42) -> 350767600
I43: 8
B47: Hormat Kami, | P47: Menyetujui,
B48: ='Covering Letter '!B43 -> PT Mitra Bakti UT | P48: ='Covering Letter '!B10 -> PT United Tractors Tbk
B54: ='Covering Letter '!B48 -> Sandy Yudha S | P54: =RIGHT('Covering Letter '!D15,18) -> Sara Kirsti Loebis
B55: Strategic Business & Sales Division Head | P55: ='Covering Letter '!D16 -> Corporate Governance & Sustainability Division Head
...

Sheet SERTIFIKASI
A1: SERTIFIKASI MANPOWER MAINTENANCE
A3: Position | B3: Scope | C3: Jenis Sertifikasi | D3: Biaya Sertifikasi | E3: Masa Berlaku | F3: Biaya/ Bulan
A4: Supervisor | B4: ME & Telcom | C4: Sertifikasi Ahli K3 Listrik | D4: 7000000 | E4: 3 Tahun | F4: =D4/36 -> 194444.44
C5: Sertifikasi TKPK 1 (Tenaga Kerja pada Ketinggian Tingkat 1) | D5: 7500000 | E5: 3 Tahun | F5: =D5/36 -> 208333.33 | G5: New
A6: Crew | B6: ME & Telcom | C6: Sertifikasi Ahli K3 Listrik | D6: 7000000 | E6: 3 Tahun | F6: =D6/36 -> 194444.44
A7: Supervisor | B7: AC | C7: Sertifikasi AC/HVAC | D7: 6500000 | E7: 3 Tahun | F7: =D7/36 -> 180555.56
C8: Sertifikasi TKPK 1 (Tenaga Kerja pada Ketinggian Tingkat 1) | D8: 7500000 | E8: 3 Tahun | F8: =D8/36 -> 208333.33 | G8: New
A9: Crew | B9: AC | C9: Sertifikasi Ahli K3 AC/HVAC | D9: 6500000 | E9: 3 Tahun | F9: =D9/36 -> 180555.56
A10: Supervisor | B10: IPAL | C10: Sertifikasi terkait keselamatan kerja dan pengelolaan instalasi air limbah. | D10: 6500000 | E10: 3 Tahun | F10: =D10/36 -> 180555.56
A11: Crew | B11: IPAL | C11: Sertifikasi terkait keselamatan kerja dan pengelolaan instalasi air limbah. | D11: 6500000 | E11: 3 Tahun | F11: =D11/36 -> 180555.56
A12: Koordinator | B12: ME & Telcom | C12: Sertifikasi Ahli K3 Listrik | D12: 7000000 | E12: 3 Tahun | F12: =D12/36 -> 194444.44

Sheet VENDOR
B1: Cost Vendor
B2: No | C2: Klasifikasi | D2: Activity | E2: Vendor | F2: Qty | G2: Satuan | H2: Unit Price | I2: Amount (Month) | J2: Amount (Year)
B4: 1 | C4: IPAL | D4: IPAL | E4: Jarwo | F4: 1 | G4: Unit | H4: 52492232 | I4: =F4*H4 -> 52492232 | J4: =I4*12 -> 6.2990679e+08
B5: 2 | C5: IPAL | D5: LAB | E5: PT Mitra Bakti UT | F5: 1 | G5: Ls | H5: 8017000 | I5: =F5*H5 -> 8017000 | J5: =I5*12 -> 96204000
H6: =SUM(H4:H5) -> 60509232 | I6: =SUM(I4:I5) -> 60509232 | J6: =SUM(J4:J5) -> 7.2611079e+08
G8: Cost 2025/ Year | H8: 1105264500
G9: SC IPAL 2024 | H9: 89669600
G10: MP 2025 | H10: 26228600
G11: Jarwo 2025 | H11: 35213750
G12: CS 2025 | H12: =RECAP!E13 -> 88902243
G13: Cost MP | H13: =RECAP!R13+RECAP!S13 -> 27374000
G14: Cost Tools | H14: =RECAP!U13 -> 1019010.5
G15: Cost Vendor | H15: =H11 -> 35213750
G16: Sisa LAB | H16: 6680833.3
H17: =H13+H14+H15+H16 -> 70287594 | I17: 71054951
H18: =H12-H17 -> 18614649

Sheet TOOLS-WORKING
B4: Lampiran 2
B5: No. | C5: ='Covering Letter '!D5 -> CS/0001/2025
B7: ADMINSITRATION
B8: No | C8: Section | D8: Tools | E8: Spec | F8: Qty | G8: Unit | H8: Unit Price | I8: Amount (Sub Total) | J8: Fee | L8: Amount (Total) | M8: Depre | N8: Amount
J9: % | K9: Amount
B10: 1 | C10: All | D10: Kertas | E10: A4 | F10: 5 | G10: Rim | H10: 62280 | I10: =F10*H10 -> 311400 | J10: 0.07 | K10: =I10*J10 -> 21798 | L10: =I10+K10 -> 333198 | M10: 1 | N10: =L10/M10 -> 333198 | P10: =N10/F10 -> 66639.6
B11: 2 | C11: All | D11: Bulpoint | F11: 1 | G11: Box | H11: 43200 | I11: =F11*H11 -> 43200 | J11: 0.07 | K11: =I11*J11 -> 3024 | L11: =I11+K11 -> 46224 | M11: 1 | N11: =L11/M11 -> 46224
B12: 3 | C12: All | D12: Printer | E12: Epson | F12: 2 | G12: Set | H12: 6280800 | I12: =F12*H12 -> 12561600 | J12: 0.07 | K12: =I12*J12 -> 879312 | L12: =I12+K12 -> 13440912 | M12: 12 | N12: 0
B13: 4 | C13: All | D13: Tinta Printer | E13: Epson | F13: 8 | G13: Set | H13: 413880 | I13: =F13*H13 -> 3311040 | J13: 0.07 | K13: =I13*J13 -> 231772.8 | L13: =I13+K13 -> 3542812.8 | M13: 1 | N13: =L13/M13 -> 3542812.8
B14: 5 | C14: All | D14: Laptop | F14: 0 | G14: Pcs | H14: 5000000 | I14: =F14*H14 -> 0 | J14: 0.07 | K14: =I14*J14 -> 0 | L14: =I14+K14 -> 0 | M14: 12 | N14: =L14/M14 -> 0
B15: 6 | C15: All | D15: Isi Label Printer | F15: 6 | G15: Pcs | H15: 287490 | I15: =F15*H15 -> 1724940 | J15: 0.07 | K15: =I15*J15 -> 120745.8 | L15: =I15+K15 -> 1845685.8 | M15: 12 | N15: =L15/M15 -> 153807.15
I16: =SUM(I10:I15) -> 17952180 | K16: =SUM(K10:K15) -> 1256652.6 | L16: =SUM(L10:L15) -> 19208833 | N16: =SUM(N10:N15) -> 4076041.9 | O16: =N16/4 -> 1019010.5 | P16: =N16/4 -> 1019010.5
B18: TOOLS ME
B19: No | C19: Section | D19: Tools | E19: Spec | F19: Qty | G19: Unit | H19: Unit Price | I19: Amount (Sub Total) | J19: Fee | L19: Amount (Total) | M19: Depre | N19: Amount
J20: % | K20: Amount
B21: 1 | C21: ME | D21: Thermal imager | F21: 0 | G21: Pcs | H21: 59938890 | I21: =F21*H21 -> 0 | J21: 0.07 | K21: =I21*J21 -> 0 | L21: 0 | M21: 24 | N21: =L21/M21 -> 0
B22: 2 | C22: ME | D22: Earth Tester | F22: 0 | G22: Pcs | H22: 4878000 | I22: =F22*H22 -> 0 | J22: 0.07 | K22: =I22*J22 -> 0 | L22: 0 | M22: 24 | N22: =L22/M22 -> 0
B23: 3 | C23: ME | D23: Clamp Meter | F23: 0 | G23: Pcs | H23: 2126400 | I23: =F23*H23 -> 0 | J23: 0.07 | K23: =I23*J23 -> 0 | L23: 0 | M23: 24 | N23: =L23/M23 -> 0
B24: 4 | C24: ME | D24: Digital Multimeter | F24: 0 | G24: Pcs | H24: 4993890 | I24: =F24*H24 -> 0 | J24: 0.07 | K24: =I24*J24 -> 0 | L24: 0 | M24: 24 | N24: =L24/M24 -> 0 | O24: https://www.googleadservices.com/pagead/aclk?sa=L&ai=DChcSEwiIvOD_kKuKAxUkq2YCHZMFIV8YABAeGgJzbQ&ae=2&aspm=1&co=1&ase=2&gclid=CjwKCAiAmfq6BhAsEiwAX1jsZ_QGaHB2PW1oPUaT4GGHHDTUeX516XLStuYNajgP-ZfTl1FDddMZJxoC3wcQAvD_BwE&ei=pIFfZ6qROfCw4-EP8qrfUQ&ohost=www.google.com&cid=CAESVuD21p6iXnmqKzspqtIJKe_Cy1xeozHnvbxt6WXSZoRw3JyvQTgr8JzGlA_AxzvdRfxSPLgEHZZoCSS5UISMcZx3wQWQMMFb8LAj_Q-IEgewMt8S1z-k&sig=AOD64_1Gq70GlvtY2XgNxXF1BRuL90wiBQ&ctype=5&q=&nis=4&sqi=2&ved=2ahUKEwiq89v_kKuKAxVw2DgGHXLVNwoQ9aACKAB6BAgHEA4&adurl=
B25: 5 | C25: ME | D25: Timah Solder | F25: 0 | G25: Pcs | H25: 94350 | I25: =F25*H25 -> 0 | J25: 0.07 | K25: =I25*J25 -> 0 | L25: 0 | M25: 12 | N25: =L25/M25 -> 0 | O25: https://www.monotaro.id/items/s018041712.html?utm_source=google&utm_medium=pla&utm_campaign=1672206402&utm_content=88187085595&gad_source=1&gclid=CjwKCAiAmfq6BhAsEiwAX1jsZ7Bd67bOftR7PMc9PNUjW3i6a9-ZVro2wd5QFDfWtXLxZCpBWxiTwxoCRQ0QAvD_BwE
B26: 6 | C26: ME | D26: Bor tangan listrik | F26: 0 | G26: Pcs | H26: 1774890 | I26: =F26*H26 -> 0 | J26: 0.07 | K26: =I26*J26 -> 0 | L26: 0 | M26: 24 | N26: =L26/M26 -> 0 | O26: https://www.monotaro.id/items/s000045017.html?utm_source=google&utm_medium=pla&utm_campaign=1672206402&utm_content=88187085595&gad_source=1&gclid=CjwKCAiAmfq6BhAsEiwAX1jsZ6i0fPuXI76hOnQrg7uWHPPMYS15tQ1lGoNZxZjgmxI-lXqRo6OsqhoCQx8QAvD_BwE | P26: New (NOK)
B27: 7 | C27: ME | D27: Bor tangan DC | F27: 0 | G27: Pcs | H27: 684600 | I27: =F27*H27 -> 0 | J27: 0.07 | K27: =I27*J27 -> 0 | L27: 0 | M27: 24 | N27: =L27/M27 -> 0 | P27: New (NOK)
B28: 8 | C28: ME | D28: Mesin Gerinda | F28: 0 | G28: Pcs | H28: 1604400 | I28: =F28*H28 -> 0 | J28: 0.07 | K28: =I28*J28 -> 0 | L28: 0 | M28: 24 | N28: =L28/M28 -> 0 | P28: New (NOK)
B29: 9 | C29: ME | D29: Vaccum Panel | F29: 0 | G29: Pcs | H29: 3519500 | I29: =F29*H29 -> 0 | J29: 0.07 | K29: =I29*J29 -> 0 | L29: 0 | M29: 24 | N29: =L29/M29 -> 0 | P29: 2024
B30: 10 | C30: ME | D30: Senter Kepala | F30: 4 | G30: Pcs | H30: 42000 | I30: =F30*H30 -> 168000 | J30: 0.07 | K30: =I30*J30 -> 11760 | L30: =I30+K30 -> 179760 | M30: 12 | N30: =L30/M30 -> 14980
B31: 11 | C31: ME | D31: Obeng Plus Kecil 100mm | F31: 0 | G31: Pcs | H31: 28000 | I31: =F31*H31 -> 0 | J31: 0.07 | K31: =I31*J31 -> 0 | L31: 0 | M31: 24 | N31: =L31/M31 -> 0 | P31: 2024
B32: 12 | C32: ME | D32: Obeng Plus Besar 200mm | F32: 0 | G32: Pcs | H32: 35000 | I32: =F32*H32 -> 0 | J32: 0.07 | K32: =I32*J32 -> 0 | L32: 0 | M32: 24 | N32: =L32/M32 -> 0 | P32: 2024
B33: 13 | C33: ME | D33: Obeng Min Kecil 100mm | F33: 0 | G33: Pcs | H33: 25000 | I33: =F33*H33 -> 0 | J33: 0.07 | K33: =I33*J33 -> 0 | L33: 0 | M33: 24 | N33: =L33/M33 -> 0 | P33: 2024
B34: 14 | C34: ME | D34: Obeng Min Besar 200mm | F34: 0 | G34: Pcs | H34: 40000 | I34: =F34*H34 -> 0 | J34: 0.07 | K34: =I34*J34 -> 0 | L34: 0 | M34: 24 | N34: =L34/M34 -> 0 | P34: 2024
B35: 15 | C35: ME | D35: Tang Snap Ring External 170mm | F35: 2 | G35: Pcs | H35: 150000 | I35: =F35*H35 -> 300000 | J35: 0.07 | K35: =I35*J35 -> 21000 | L35: =I35+K35 -> 321000 | M35: 12 | N35: =L35/M35 -> 26750 | P35: 2025
B36: 16 | C36: ME | D36: Tang Snap Ring Internal 170mm | F36: 2 | G36: Pcs | H36: 150000 | I36: =F36*H36 -> 300000 | J36: 0.07 | K36: =I36*J36 -> 21000 | L36: =I36+K36 -> 321000 | M36: 24 | N36: =L36/M36 -> 13375 | P36: 2025
B37: 17 | C37: ME | D37: Tang Potong / Plier Side Cutting 6" | F37: 3 | G37: Pcs | H37: 58000 | I37: =F37*H37 -> 174000 | J37: 0.07 | K37: =I37*J37 -> 12180 | L37: =I37+K37 -> 186180 | M37: 24 | N37: =L37/M37 -> 7757.5 | P37: 2025
B38: 18 | C38: ME | D38: Tang Jepit / Long Nouse 6" | F38: 0 | G38: Pcs | H38: 88000 | I38: =F38*H38 -> 0 | J38: 0.07 | K38: =I38*J38 -> 0 | L38: 0 | M38: 24 | N38: =L38/M38 -> 0 | P38: 2024
B39: 19 | C39: ME | D39: Tang Kombinasi / Plier Combination 7" | F39: 0 | G39: Pcs | H39: 63000 | I39: =F39*H39 -> 0 | J39: 0.07 | K39: =I39*J39 -> 0 | L39: 0 | M39: 24 | N39: =L39/M39 -> 0 | P39: 2024
B40: 20 | C40: ME | D40: Tang ripet | F40: 4 | G40: Pcs | H40: 100080 | I40: =F40*H40 -> 400320 | J40: 0.07 | K40: =I40*J40 -> 28022.4 | L40: =I40+K40 -> 428342.4 | M40: 12 | N40: =L40/M40 -> 35695.2 | P40: 2024
B41: 21 | C41: ME | D41: Kunci Pas 6-7 | F41: 2 | G41: Pcs | H41: 35900 | I41: =F41*H41 -> 71800 | J41: 0.07 | K41: =I41*J41 -> 5026 | L41: 0 | M41: 24 | N41: =L41/M41 -> 0 | P41: 2024
B42: 22 | C42: ME | D42: Kunci Pas 8-9 | F42: 2 | G42: Pcs | H42: 30000 | I42: =F42*H42 -> 60000 | J42: 0.07 | K42: =I42*J42 -> 4200 | L42: 0 | M42: 24 | N42: =L42/M42 -> 0 | P42: 2024
B43: 23 | C43: ME | D43: Kunci Pas 10-11 | F43: 2 | G43: Pcs | H43: 35000 | I43: =F43*H43 -> 70000 | J43: 0.07 | K43: =I43*J43 -> 4900 | L43: 0 | M43: 24 | N43: =L43/M43 -> 0 | P43: 2024
B44: 24 | C44: ME | D44: Kunci Pas 12-13 | F44: 2 | G44: Pcs | H44: 40000 | I44: =F44*H44 -> 80000 | J44: 0.07 | K44: =I44*J44 -> 5600 | L44: 0 | M44: 24 | N44: =L44/M44 -> 0 | P44: 2024
B45: 25 | C45: ME | D45: Kunci Pas 14-15 | F45: 2 | G45: Pcs | H45: 45000 | I45: =F45*H45 -> 90000 | J45: 0.07 | K45: =I45*J45 -> 6300 | L45: 0 | M45: 24 | N45: =L45/M45 -> 0 | P45: 2024
...

Sheet TOOLS
B5: Lampiran 2
B6: No. | C6: ='[1]Covering Letter '!D5 -> CS/0202/2025
B8: BIAYA PERALATAN MAINTENANCE PER BULAN
B9: TAHUN 2025
B10: NAMA | D10: PT MITRA BAKTI UT
B11: AREA PELAYANAN | D11: PT UNITED TRACTORS TBK - HEAD OFFICE
B13: A. PERALATAN ADMINISTRATION
B14: No | C14: Keterangan | D14: Kuantitas | F14: Harga | G14: Biaya | H14: Depr | I14: Biaya / bln
B15: 1 | C15: Kertas | D15: 5 | E15: Rim | F15: 66639.6 | G15: =D15*F15 -> 333198 | H15: 1 | I15: =G15/H15 -> 333198
B16: 2 | C16: Bulpoint | D16: 1 | E16: Box | F16: 46224 | G16: =D16*F16 -> 46224 | H16: 1 | I16: =G16/H16 -> 46224
B17: 3 | C17: Printer | D17: 2 | E17: Set | F17: 6720456 | G17: 0 | H17: 12 | I17: =G17/H17 -> 0
B18: 4 | C18: Tinta Printer | D18: 8 | E18: Set | F18: 442851.6 | G18: =F18*D18 -> 3542812.8 | H18: 1 | I18: =G18/H18 -> 3542812.8
B19: 5 | C19: Laptop | D19: 9 | E19: Pcs | F19: 5350000 | G19: 0 | H19: 12 | I19: =G19/H19 -> 0
B20: 6 | C20: Isi Label Printer | D20: 6 | E20: Pcs | F20: 307614.3 | G20: =F20*D20 -> 1845685.8 | H20: 12 | I20: =G20/H20 -> 153807.15
B21: TOTAL | I21: =SUM(I15:I20) -> 4076042 | J21: =I21/4 -> 1019010.5
J22: =I21/107% -> 3809385
B23: B. PERALATAN ME | J23: =I21-J22 -> 266656.95
B24: No | C24: Keterangan | D24: Kuantitas | F24: Harga | G24: Biaya | H24: Depr | I24: Biaya / bln
B25: 1 | C25: Thermal Imager | D25: 0 | E25: Pcs | F25: 64134612 | G25: =D25*F25 -> 0 | H25: 24 | I25: =G25/H25 -> 0
B26: 2 | C26: Earth Tester | D26: 0 | E26: Pcs | F26: 5219460 | G26: =D26*F26 -> 0 | H26: 24 | I26: =G26/H26 -> 0
B27: 3 | C27: Clamp Meter | D27: 0 | E27: Pcs | F27: 2275248 | G27: =D27*F27 -> 0 | H27: 24 | I27: =G27/H27 -> 0
B28: 4 | C28: Digital Multimeter | D28: 0 | E28: Pcs | F28: 5343462.3 | G28: =D28*F28 -> 0 | H28: 24 | I28: =G28/H28 -> 0
B29: 5 | C29: Timah Solder | D29: 0 | E29: Pcs | F29: 100954.5 | G29: =D29*F29 -> 0 | H29: 12 | I29: =G29/H29 -> 0
B30: 6 | C30: Bor Tangan Listrik | D30: 0 | E30: Pcs | F30: 1899132.3 | G30: =D30*F30 -> 0 | H30: 24 | I30: =G30/H30 -> 0
B31: 7 | C31: Bor Tangan DC | D31: 0 | E31: Pcs | F31: 732522 | G31: =D31*F31 -> 0 | H31: 24 | I31: =G31/H31 -> 0
B32: 8 | C32: Mesin Gerinda | D32: 0 | E32: Pcs | F32: 1716708 | G32: =D32*F32 -> 0 | H32: 24 | I32: =G32/H32 -> 0
B33: 9 | C33: Vaccum Panel | D33: 0 | E33: Pcs | F33: 3765865 | G33: =D33*F33 -> 0 | H33: 24 | I33: =G33/H33 -> 0
B34: 10 | C34: Senter Kepala | D34: 4 | E34: Pcs | F34: 44940 | G34: =D34*F34 -> 179760 | H34: 12 | I34: =G34/H34 -> 14980
B35: 11 | C35: Obeng Plus Kecil 100mm | D35: 0 | E35: Pcs | F35: 29960 | G35: =D35*F35 -> 0 | H35: 24 | I35: =G35/H35 -> 0
B36: 12 | C36: Obeng Plus Besar 200mm | D36: 0 | E36: Pcs | F36: 37450 | G36: =D36*F36 -> 0 | H36: 24 | I36: =G36/H36 -> 0
... B44: 20 | C44: Tang Ripet | D44: 4 | E44: Pcs | F44: 107085.6 | G44: =D44*F44 -> 428342.4 | H44: 12 | I44: =G44/H44 -> 35695.2
B45: 21 | C45: Kunci Pas 6-7 | D45: 2 | E45: Pcs | F45: 38413 | G45: =D45*F45*0 -> 0 | H45: 24 | I45: =G45/H45 -> 0
B46: 22 | C46: Kunci Pas 8-9 | D46: 2 | E46: Pcs | F46: 32100 | G46: =D46*F46*0 -> 0 | H46: 24 | I46: =G46/H46 -> 0
B47: 23 | C47: Kunci Pas 10-11 | D47: 2 | E47: Pcs | F47: 37450 | G47: =D47*F47*0 -> 0 | H47: 24 | I47: =G47/H47 -> 0
B48: 24 | C48: Kunci Pas 12-13 | D48: 2 | E48: Pcs | F48: 42800 | G48: =D48*F48*0 -> 0 | H48: 24 | I48: =G48/H48 -> 0
B49: 25 | C49: Kunci Pas 14-15 | D49: 2 | E49: Pcs | F49: 48150 | G49: =D49*F49*0 -> 0 | H49: 24 | I49: =G49/H49 -> 0
B50: 26 | C50: Kunci Pas 16-17 | D50: 2 | E50: Pcs | F50: 53500 | G50: =D50*F50*0 -> 0 | H50: 24 | I50: =G50/H50 -> 0
B51: 27 | C51: Kunci Inggris | D51: 2 | E51: Pcs | F51: 138030 | G51: =D51*F51*0 -> 0 | H51: 24 | I51: =G51/H51 -> 0
B52: 28 | C52: Cutter | D52: 10 | E52: Pcs | F52: 21400 | G52: =D52*F52 -> 214000 | H52: 24 | I52: =G52/H52 -> 8916.6667
B53: 29 | C53: Ear Plug | D53: 2 | E53: Pcs | F53: 18725 | G53: =D53*F53 -> 37450 | H53: 24 | I53: =G53/H53 -> 1560.4167
...

Sheet TOOLS-PRINT
B4: Lampiran 2
B5: No. | C5: ='Covering Letter '!D5 -> CS/0001/2025
B7: BIAYA PERALATAN MAINTENANCE PER BULAN
B8: TAHUN 2025
B9: NAMA | D9: PT MITRA BAKTI UT
B10: AREA PELAYANAN | D10: PT UNITED TRACTORS TBK - HEAD OFFICE
B12: A. PERALATAN ADMINISTRATION
B13: No | C13: Keterangan | D13: Kuantitas | F13: Depr
B14: 1 | C14: Kertas | D14: 5 | E14: Rim | F14: 1
B15: 2 | C15: Bulpoint | D15: 1 | E15: Box | F15: 1
B16: 3 | C16: Printer | D16: 0 | E16: Set | F16: 12
B17: 4 | C17: Tinta Printer | D17: 8 | E17: Set | F17: 1
B18: 5 | C18: Laptop | D18: 0 | E18: Pcs | F18: 12
B19: 6 | C19: Isi Label Printer | D19: 6 | E19: Pcs | F19: 12
B20: TOTAL | G20: =#REF!/4 -> #REF!
B22: B. PERALATAN ME
B23: No | C23: Keterangan | D23: Kuantitas | F23: Depr
B24: 1 | C24: Thermal Imager | D24: 0 | E24: Pcs | F24: 24
B25: 2 | C25: Earth Tester | D25: 0 | E25: Pcs | F25: 24
B26: 3 | C26: Clamp Meter | D26: 0 | E26: Pcs | F26: 24
B27: 4 | C27: Digital Multimeter | D27: 0 | E27: Pcs | F27: 24
B28: 5 | C28: Timah Solder | D28: 0 | E28: Pcs | F28: 12
B29: 6 | C29: Bor Tangan Listrik | D29: 0 | E29: Pcs | F29: 24
B30: 7 | C30: Bor Tangan DC | D30: 0 | E30: Pcs | F30: 24
B31: 8 | C31: Mesin Gerinda | D31: 0 | E31: Pcs | F31: 24
B32: 9 | C32: Vaccum Panel | D32: 0 | E32: Pcs | F32: 24
B33: 10 | C33: Senter Kepala | D33: 4 | E33: Pcs | F33: 12
B34: 11 | C34: Obeng Plus Kecil 100mm | D34: 0 | E34: Pcs | F34: 24
B35: 12 | C35: Obeng Plus Besar 200mm | D35: 0 | E35: Pcs | F35: 24
... B81: 58 | C81: Smoke Test 70gr | D81: 400 | E81: botol | F81: 12
B82: TOTAL
B84: C. PERALATAN AC
B85: No | C85: Keterangan | D85: Kuantitas | F85: Depr
B86: 1 | C86: Selang Pompa Steam AC | D86: 0 | E86: Pcs | F86: 24
B87: 2 | C87: Plastik Service AC | D87: 3 | E87: Pcs | F87: 1
B88: 3 | C88: Selang Air | D88: 3 | E88: Pcs | F88: 12
B89: 4 | C89: Kabel Roll Nym 30 Meter | D89: 0 | E89: Pcs | F89: 24
B90: 5 | C90: Kanebo | D90: 5 | E90: Pcs | F90: 2
B91: 6 | C91: Senter Kepala/Headlamp | D91: 4 | E91: Pcs | F91: 3
B92: 7 | C92: Tangga Lipat | D92: 0 | E92: Pcs | F92: 24
...

Sheet LIST MP
B5: Lampiran 2
B6: No. | C6: ='Covering Letter '!D5 -> CS/0001/2025
B9: TENAGA KERJA JOB SUPPLY MAINTENANCE
B10: NAMA | D10: : PT MITRA BAKTI UT
B11: AREA PELAYANAN | D11: : PT UNITED TRACTORS TBK
B13: NO | C13: NAMA MANPOWER | D13: POSISI | E13: LOKASI KERJA
B14: 1 | C14: Haryono | D14: SPV. AC | E14: Non UT HO
B15: 2 | C15: Bambang Agi Siswandi | D15: AC | E15: Non UT HO
B16: 3 | C16: Edi Purwanto | D16: AC | E16: Non UT HO
B17: 4 | C17: Muhammad Ridwan | D17: AC | E17: Non UT HO
B18: 5 | C18: Eko Krisdianto | D18: AC | E18: Non UT HO
B19: 6 | C19: Dwi Riszi Aripyanto | D19: SPV. AC | E19: UT HO & Employee Center
B20: 7 | C20: Hadi Susanto | D20: AC | E20: UT HO & Employee Center
B21: 8 | C21: Joko Santoso | D21: AC | E21: UT HO & Employee Center
B22: 9 | C22: Demig Ali Bimawan | D22: AC | E22: UT HO & Employee Center
B23: 10 | C23: Dimas Solih Prastiaji | D23: AC | E23: UT HO & Employee Center
B24: 11 | C24: Akhmad Taryono | D24: SPV. ME | E24: UT HO & Employee Center
B25: 12 | C25: Bambang Sutrisno | D25: ME | E25: UT HO & Employee Center
... B51: 38 | C51: Bayu Setiawan | D51: Civil | E51: PPI Cakung
