Workbook
Name \0: [1]COVER!#REF!
Name \0: [1]COVER!#REF!
Name \A: #REF!
Name \A: #REF!
Name \B: #REF!
Name \B: #REF!
Name \C: #REF!
Name \C: #REF!
Name \D: #REF!
Name \D: #REF!
Name \E: #REF!
Name \E: #REF!
Name \E1: [2]H.Satuan!#REF!
Name \F: #REF!
Name \F: #REF!
Name \FA: #REF!
Name \FA: #REF!
Name \G: #REF!
Name \G: #REF!
Name \H: #REF!
Name \H: #REF!
Name \I: #REF!
Name \I: #REF!
Name \J: #REF!
Name \J: #REF!
Name \JUSTIFY: #REF!
Name \JUSTIFY: #REF!
Name \K: #REF!
Name \K: #REF!
Name \L: #REF!
Name \L: #REF!
Name \LOCATION: #REF!
Name \LOCATION: #REF!
Name \M: #REF!
Name \M: #REF!
Name \N: #REF!
Name \N: #REF!
Name \O: #REF!
Name \O: #REF!
Name \P: #REF!
Name \P: #REF!
Name \q: #N/A
Name \R: #REF!
Name \R: #REF!
Name \S: #REF!
Name \S: #REF!
Name \SIZE: #REF!
Name \SIZE: #REF!
Name \T: #REF!
Name \T: #REF!
Name \U: #REF!
Name \U: #REF!
Name \V: #REF!
Name \V: #REF!
Name \W: #REF!
Name \W: #REF!
Name \WQ: '[3]BAG-2'!#REF!
Name \x: [4]Cover!#REF!
Name \Y: #REF!
Name \Y: #REF!

Sheet 00. CS Information Form
B5: COST STRUCTURE INFORMATION FORM
B7: A. GENERAL INFORMATION
B8: 1 | C8: Customer Name | E8: : | F8: ='01. Covering Letter '!B10 -> PT United Tractors Tbk
B9: 2 | C9: Site / Location | E9: : | F9: DKI Jakarta
B10: 3 | C10: Project Name | E10: : | F10: Jasa Penyedia Tenaga Kerja Cleaning Service Kanamoto
B11: 4 | C11: Service Type | E11: : | F11: v | G11: Routine | I11: Incidental
B12: 5 | C12: Nilai Cost Structure | E12: : | F12: ='02. Cost Structure MP'!I52 -> 25784400
B13: 6 | C13: Cost of Revenue | E13: : | F13: ='02. Cost Structure MP'!I73 -> 23617582
B14: 7 | C14: Gross Margin | E14: : | F14: =F12-F13 -> 2166817.7 | I14: =F14/F12 -> 0.084035995
B16: B. KEY COST COMPOSITION
B17: 1 | C17: Manpower
C18: Qty | E18: : | F18: ='02. Cost Structure MP'!I51 -> 3
C19: Note | E19: : | G19: New Hire | H19: v | I19: Existing | K19: Others
B20: 2 | C20: Subcontractor (For Incidental Case)
C21: Vendor Name
C22: 1. | D22: N/A | E22: :
C23: 2. | D23: N/A | E23: :
C24: 3. | D24: N/A | E24: :
C25: 4. | D25: N/A | E25: :
C26: dst
B27: 3 | C27: Operational Strategic | E27: : | F27: - Sourcing kandidat dari Mitra Bakti Akademi
F28: dst
F29: dst
F30: dst
F31: dst
B34: C. INFORMATION TO
D36: Operation | G36: Human Capital | K36: Procurement
D38: Finance | G38: General Affairs | K38: Admin Billing

Sheet 01. Covering Letter 
F4: Jakarta, 07 Januari 2026
B5: No. | C5: : | D5: LD/01074/2025
B6: Perihal | C6: : | D6: Penawaran Harga Jasa Penyedia Tenaga Kerja Support Yard
B7: Lampiran | C7: : | D7: 1 Lembar
B9: Kepada Yth;
B10: PT United Tractors Tbk
B11: Jl. Raya Bekasi KM 22
B12: Kec. Cakung, Kota Jakarta Timur
B13: Daerah Khusus Ibukota Jakarta 13910
B15: Up | C15: : | D15: Bapak Anuar Hasahatan
D16: Department Head Logam
B19: Dengan hormat,
B20: Sehubungan dengan adanya kebutuhan Penyedia Jasa Tenaga Kerja di perusahaan Bapak/Ibu, bersama ini kami sampaikan penawaran dari PT Mitra Bakti UT sebagai berikut:
B22: - Penyedia Jasa Tenaga Kerja (rincian terlampir)
B23: Rp | D23: ='02. Cost Structure MP'!I52 -> 25784400
B25: Note :
B26: 1. Harga ini berlaku untuk tahun 2026.
B27: 2. Harga belum termasuk PPN 11%.
B28: 3. Harga tersebut sudah termasuk BPJS Kesehatan, BPJS Ketenagakerjaan (BPJS Jaminan Kecelakaan Kerja, BPJS -
B29: Jaminan Kematian, BPJS Jaminan Hari Tua, BPJS Jaminan Pensiun), Kompensasi Kerja (PP no 35 Tahun 2021),
B30: Tunjangan Hari Raya (THR), dan Pakaian Kerja.
B31: 4. Perhitungan dan pelaksanaan lembur mengikuti ketentuan peraturan ketenagakerjaan (Disnaker).
B32: 5. Lembur ditagihkan sesuai aktual dengan management fee sebesar 5%.
B33: 6. Harga sudah termasuk biaya pelatihan (training) yang meliputi Behavioral Training dan Technical Training.
B34: 7. Harga belum termasuk biaya sertifikasi. Biaya tersebut akan disesuaikan dengan kebutuhan User dan ditagihkan
B35: sesuai aktual dengan management fee sebesar 5%.
B36: 8. Biaya Medical Check-Up (MCU) sudah termasuk dalam harga; apabila terdapat kelebihan biaya akan ditagihkan sesuai
... B52: Operation Division Head

Sheet 02. Cost Structure MP
B5: Lampiran 1
B6: No. | C6: ='01. Covering Letter '!D5 -> LD/01074/2025
B8: STRUKTUR BIAYA JASA TENAGA KERJA
B9: TAHUN 2026
B10: AREA DKI JAKARTA
B12: NO | C12: URAIAN | F12: SUPPORT YARD MARKETING | I12: KETERANGAN | K12: Price 2025 | L12: Price 2026 | M12: Price Incrase | O12: Remarks
F13: MARYADI | G13: SAHUPI | H13: WAHYUDDIN | K13: 16251000 | L13: =I52 -> 25784400 | M13: =L13-K13 -> 9533400 | N13: =M13/K13 -> 0.58663467
B14: I | C14: FIXED COST | F14: =SUM(F15,F18:F20) -> 7271594.6 | G14: =SUM(G15,G18:G20) -> 7271594.6 | H14: =SUM(H15,H18:H20) -> 7271594.6 | K14: UMK 2025 | L14: UMK 2026 | M14: UMK Incrase | O14: Remarks
B15: 1 | C15: Upah | F15: =SUM(F16:F17) -> 5729876 | G15: =SUM(G16:G17) -> 5729876 | H15: =SUM(H16:H17) -> 5729876 | I15: Upah Tenaga Kerja (UMK 2026) | K15: 5396760 | L15: 5729876 | M15: =L15-K15 -> 333116 | N15: =M15/K15 -> 0.061725183
C16: Gaji Pokok | F16: =$L16 -> 5229876 | G16: =$L16 -> 5229876 | H16: =$L16 -> 5229876 | K16: =K15-500000 -> 4896760 | L16: =L15-500000 -> 5229876 | M16: =L16-K16 -> 333116 | N16: =M16/K16 -> 0.068027839
C17: Tunjangan Tetap | F17: 500000 | G17: 500000 | H17: 500000 | K17: 500000 | L17: 500000 | M17: =L17-K17 -> 0 | N17: =M17/K17 -> 0
B18: 2 | C18: BPJS | E18: 0.1024 | F18: =F15*$E$18 -> 586739.3 | G18: =G15*$E$18 -> 586739.3 | H18: =H15*$E$18 -> 586739.3 | I18: Mengikuti Regulasi Pemerintah (JKK = 0,24%, JKM = 0,30%, JHT = 3,70%, JP = 2%, JK = 4%)
B19: 3 | C19: THR | F19: =F15/12 -> 477489.67 | G19: =G15/12 -> 477489.67 | H19: =H15/12 -> 477489.67 | I19: Upah /12
B20: 4 | C20: Pesangon (PKWTT) / Kompensasi PKWT (UUCK) | F20: =F15/12 -> 477489.67 | G20: =G15/12 -> 477489.67 | H20: =H15/12 -> 477489.67 | I20: Upah /12
B21: II | C21: OVERTIME | F21: =F24+F26 -> 0 | G21: =G24+G26 -> 0 | H21: =H24+H26 -> 0
B22: 1 | C22: TUL | F22: =F15/173 -> 33120.671 | G22: =G15/173 -> 33120.671 | H22: =H15/173 -> 33120.671 | I22: Upah /173
B23: 2 | C23: Jam Lembur | F23: 0 | G23: 0 | H23: 0 | I23: Sesuai Aktual Dilapangan
B24: 3 | C24: Upah Lembur | F24: =F22*F23 -> 0 | G24: =G22*G23 -> 0 | H24: =H22*H23 -> 0 | I24: Ditagihkan Sesuai Aktual Dengan Management Fee 5%
B25: 4 | C25: Jam Lembur (Hari Besar) | F25: 0 | G25: 0 | H25: 0 | I25: Sesuai Aktual Dilapangan
B26: 5 | C26: Upah Lembur (Hari Besar) | F26: 0 | G26: 0 | H26: 0 | I26: Ditagihkan Sesuai Aktual Dengan Management Fee 5%
B27: III | C27: VARIABLE COST | F27: =SUM(F28:F36) -> 686500 | G27: =SUM(G28:G36) -> 686500 | H27: =SUM(H28:H36) -> 686500
B28: 1 | C28: Medical Check Up (MCU) | F28: ='03. Variable Cost Services'!$U16 -> 65000 | G28: ='03. Variable Cost Services'!$U16 -> 65000 | H28: ='03. Variable Cost Services'!$U16 -> 65000 | I28: Kelebihan biaya MCU ditagihkan sesuai aktual
B29: 2 | C29: Seragam | F29: ='03. Variable Cost Services'!$U28 -> 156500 | G29: ='03. Variable Cost Services'!$U28 -> 156500 | H29: ='03. Variable Cost Services'!$U28 -> 156500 | I29: 3 Pasang Per Tahun (Baju & Celana) & Safety Shoes
B30: 3 | C30: APD | F30: 0 | G30: 0 | H30: 0 | I30: Disediakan oleh User
B31: 4 | C31: Training (Development) | F31: 65000 | G31: 65000 | H31: 65000 | I31: Behavioral Training dan Technical Training
B32: 5 | C32: Tunjangan Jabatan | F32: 0 | G32: 0 | H32: 0
B33: 6. Harga sudah termasuk biaya pelatihan (training) yang meliputi Behavioral Training dan Technical Training. | C33: Tunjangan Beras | F33: 0 | G33: 0 | H33: 0
B34: 7 | C34: Tunjangan Tempat Tinggal | F34: 0 | G34: 0 | H34: 0
B35: 8 | C35: Insentif Jam Kerja | F35: 0 | G35: 0 | H35: 0
B36: 6 | C36: Overhead Expenses | F36: =SUM(F37:F45) -> 400000 | G36: =SUM(G37:G45) -> 400000 | H36: =SUM(H37:H45) -> 400000
C37: Employee Engagement Visit (Sambung Rasa) | F37: 115000 | G37: 115000 | H37: 115000
C38: Training (Development) | F38: =65000*0 -> 0 | G38: =65000*0 -> 0 | H38: =65000*0 -> 0
C39: Sertifikasi (Certification) | F39: 0 | G39: 0 | H39: 0
C40: Recruitment | F40: 50000 | G40: 50000 | H40: 50000
C41: Employee Welfare & Compassion Fund (Suka Duka) | F41: 45000 | G41: 45000 | H41: 45000
C42: Replacement (Cadangan Pengganti Tenaga Kerja) | F42: =35000*0 -> 0 | G42: =35000*0 -> 0 | H42: =35000*0 -> 0
C43: Legal Compliance (Perizinan & Administrasi) | F43: 0 | G43: 0 | H43: 0
C44: Regional Coordination (Koordinasi Wilayah) | F44: 0 | G44: 0 | H44: 0
C45: Operational Support | F45: 190000 | G45: 190000 | H45: 190000
C46: TOTAL I + II + III | F46: =F14+F21+F27 -> 7958094.6 | G46: =G14+G21+G27 -> 7958094.6 | H46: =H14+H21+H27 -> 7958094.6
...

Sheet 03. Variable Cost Services
B5: Lampiran 2
B6: No. | C6: ='01. Covering Letter '!D5 -> LD/01074/2025
B8: JASA PENYEDIA TENAGA KERJA CLEANING SERVICE TAHUN 2026
B9: VARIABLE COST
C10: SERVICE PROVIDER | K10: : PT MITRA BAKTI UT
C11: SERVICE LOCATION/ SITE | K11: : PT UNITED TRACTORS TBK HEAD OFFICE
B13: MEDICAL CHECK UP
C14: PROCUREMENT
B15: NO | C15: PRODUCT NAME | D15: BRAND | E15: SPESIFICATION | F15: MATERIAL | G15: VARIANT | H15: N.UOM | I15: UOM | J15: PART CODE | K15: QTY | M15: PROC PRICE | N15: DELIVERY FEE | O15: MARK UP | P15: UNIT PRICE | Q15: FREQ | R15: TOTAL | S15: REAL COST | T15: BUDGET | U15: PUBLISH | V15: DEVIASI | Y15: 2025
B16: 1 | C16: MEDICAL CHECK UP | K16: 1 | L16: Ls | M16: =601000*110% -> 661100 | N16: 0 | O16: 1.1 | P16: =(M16+N16)*O16 -> 727210 | Q16: 12 | R16: =K16*P16/Q16 -> 60600.833 | S16: =K16*(M16+N16)/Q16 -> 55091.667 | T16: =R16/105% -> 57715.079 | U16: 65000 | V16: =U16-T16 -> 7284.9206 | W16: =V16/U16 -> 0.1120757 | Y16: 60000
B17: TOTAL | R17: =SUM(R16:R16) -> 60600.833 | S17: =SUM(S16:S16) -> 55091.667 | T17: =SUM(T16:T16) -> 57715.079 | U17: =SUM(U16:U16) -> 65000 | V17: =SUM(V16:V16) -> 7284.9206 | W17: =V17/U17 -> 0.1120757
B19: NO | C19: PRODUCT NAME | D19: BRAND | E19: SPESIFICATION | F19: MATERIAL | G19: VARIANT | H19: N.UOM | I19: UOM | J19: PART CODE | K19: QTY | M19: PROC PRICE | N19: DELIVERY FEE | O19: MARK UP | P19: UNIT PRICE | Q19: FREQ | R19: TOTAL | S19: REAL COST | T19: BUDGET | U19: PUBLISH | V19: DEVIASI
B20: A. SERAGAM | R20: =SUM(R21:R22) -> 85050 | S20: =SUM(S21:S22) -> 70875 | T20: =SUM(T21:T22) -> 81000 | U20: =SUM(U21:U22) -> 89500 | V20: =SUM(V21:V22) -> 8500 | W20: =V20/U20 -> 0.094972067
B21: 1 | C21: BAJU MAINTENANCE | E21: LENGAN PENDEK | K21: 3 | L21: pcs | M21: =140000*105% -> 147000 | N21: 0 | O21: 1.2 | P21: =(M21+N21)*O21 -> 176400 | Q21: 12 | R21: =K21*P21/Q21 -> 44100 | S21: =K21*(M21+N21)/Q21 -> 36750 | T21: =R21/105% -> 42000 | U21: 46500 | V21: =U21-T21 -> 4500 | W21: =V21/U21 -> 0.096774194
B22: 2 | C22: CELANA JEANS | K22: 3 | L22: pcs | M22: =130000*105% -> 136500 | N22: 0 | O22: 1.2 | P22: =(M22+N22)*O22 -> 163800 | Q22: 12 | R22: =K22*P22/Q22 -> 40950 | S22: =K22*(M22+N22)/Q22 -> 34125 | T22: =R22/105% -> 39000 | U22: 43000 | V22: =U22-T22 -> 4000 | W22: =V22/U22 -> 0.093023256
B23: B. ALAT PELINDUNG DIRI (APD) | R23: =SUM(R24:R27) -> 63682.5 | S23: =SUM(S24:S27) -> 53068.75 | T23: =SUM(T24:T27) -> 55376.087 | U23: =SUM(U24:U27) -> 67000 | V23: =SUM(V24:V27) -> 11623.913 | W23: =V23/U23 -> 0.17349124 | X23: 0
B24: 1 | C24: SAFETY HELMET | D24: BESGARD | G24: WHITE | K24: 1 | L24: Pcs | M24: =88000*0% -> 0 | N24: 0 | O24: 1.2 | P24: =(M24+N24)*O24 -> 0 | Q24: 12 | R24: =K24*P24/Q24 -> 0 | S24: =K24*(M24+N24)/Q24 -> 0 | T24: =R24/115% -> 0 | U24: =17000*0 -> 0 | V24: =U24-T24 -> 0 | W24: =V24/U24 -> #DIV/0!
B25: 2 | C25: SAFETY GLASSES | D25: KRISBOW | K25: 1 | L25: Pcs | M25: =80000*0% -> 0 | N25: 0 | O25: 1.2 | P25: =(M25+N25)*O25 -> 0 | Q25: 12 | R25: =K25*P25/Q25 -> 0 | S25: =K25*(M25+N25)/Q25 -> 0 | T25: =R25/115% -> 0 | U25: =15000*0 -> 0 | V25: =U25-T25 -> 0 | W25: =V25/U25 -> #DIV/0!
B26: 3 | C26: SAFETY VEST | K26: 1 | L26: Pcs | M26: =60000*0% -> 0 | N26: 0 | O26: 1.2 | P26: =(M26+N26)*O26 -> 0 | Q26: 12 | R26: =K26*P26/Q26 -> 0 | S26: =K26*(M26+N26)/Q26 -> 0 | T26: =R26/115% -> 0 | U26: =22000*0 -> 0 | V26: =U26-T26 -> 0 | W26: =V26/U26 -> #DIV/0!
B27: 4 | C27: SAFETY SHOES | D27: KINGS | E27: 0 | F27: 0 | G27: BLACK | H27: 0 | I27: 0 | J27: KWD206X | K27: 1 | L27: Pcs | M27: =606500*105% -> 636825 | N27: 0 | O27: 1.2 | P27: =(M27+N27)*O27 -> 764190 | Q27: 12 | R27: =K27*P27/Q27 -> 63682.5 | S27: =K27*(M27+N27)/Q27 -> 53068.75 | T27: =R27/115% -> 55376.087 | U27: 67000 | V27: =U27-T27 -> 11623.913 | W27: =V27/U27 -> 0.17349124
B28: TOTAL (A+B) | R28: =R20+R23 -> 148732.5 | S28: =S20+S23 -> 123943.75 | T28: =T20+T23 -> 136376.09 | U28: =U20+U23 -> 156500 | V28: =V20+V23 -> 20123.913 | W28: =V28/U28 -> 0.1285873
