Workbook

Sheet Tools Kit
B2: Tools & Consumable AC Split | H2: Tools & Consumable AC Kaset
B3: Kategori | C3: No | D3: Nama Item | E3: Jumlah Ideal | F3: Keterangan | H3: Kategori | I3: No | J3: Nama Item | K3: Jumlah Ideal | L3: Keterangan
B4: Tools (Peralatan) | C4: 1 | D4: Pompa Steam Portable | E4: 1 unit | F4: Untuk mencuci evaporator & outdoor | H4: Tools (Peralatan) | I4: 1 | J4: Pompa Steam Tekanan Tinggi | K4: 1 unit | L4: Membersihkan coil besar
C5: 2 | D5: Selang Pompa Steam (5–10 m) | E5: 1 pcs | F5: Terhubung ke pompa steam | I5: 2 | J5: Selang Pompa Steam (10–15 m) | K5: 1 pcs | L5: Jangkauan plafon tinggi
C6: 3 | D6: Plastik Service AC | E6: 1 pcs | F6: Penampung air cucian indoor | I6: 3 | J6: Plastik / terpal Penutup Cassette | K6: 1 pcs | L6: Penampung air cucian
C7: 4 | D7: Tangga Lipat (2 m) | E7: 1 unit | F7: Akses ke unit indoor/outdoor | I7: 4 | J7: Tangga Tinggi / Scaffolding | K7: 1 unit | L7: Akses ke unit di plafon
C8: 5 | D8: Mesin Vacuum AC Mini | E8: 1 unit | F8: Menghisap udara & kelembapan sistem | I8: 5 | J8: Mesin Vacuum AC | K8: 1 unit | L8: Menghisap udara/freon
C9: 6 | D9: Manifold Gauge | E9: 1 unit | F9: Pengukur tekanan freon | I9: 6 | J9: Manifold Gauge | K9: 1 unit | L9: Ukur tekanan freon
C10: 7 | D10: Thermogun | E10: 1 unit | F10: Pengukur suhu udara | I10: 7 | J10: Thermogun | K10: 1 unit | L10: Ukur suhu udara keluaran
C11: 8 | D11: Obeng Set (Min & Plus) | E11: 1 set | F11: Bongkar pasang casing | I11: 8 | J11: Obeng Set Lengkap | K11: 1 set | L11: Bongkar panel indoor
C12: 9 | D12: Kanebo / Lap Microfiber | E12: 2 pcs | F12: Pengering akhir | I12: 9 | J12: Bor Battery | K12: 1 unit | L12: Buka baut plafon cepat
C13: 10 | D13: tas / toolbox | E13: 1 unit | F13: Membawa peralatan & bahan | I13: 10 | J13: Tang Kombinasi & Kunci Inggris | K13: 1 set | L13: Kencangkan fitting pipa
C14: 11 | D14: Senter Kepala | E14: 1 pcs | F14: Penerangan di area indoor | I14: 11 | J14: Ember Besar (20 L) | K14: 1 pcs | L14: Tampung air cucian
C15: 12 | D15: Meteran 5 m | E15: 1 pcs | F15: Pengukuran pipa & jarak | I15: 12 | J15: Kanebo / Lap Microfiber | K15: 2 pcs | L15: Pengering akhir
C16: 13 | D16: Cutter & Tang Kombinasi | E16: 1 set | F16: Perbaikan dan pemotongan ringan | I16: 13 | J16: Senter Kepala | K16: 1 pcs | L16: Visibilitas di area plafon
C17: 14 | D17: Clamp Meter | E17: 1 set | F17: Untuk cek arus dan tegangan, penting dalam diagnosis kerusakan. | I17: 14 | J17: Clamp Meter | K17: 1 set | L17: Untuk cek arus dan tegangan, penting dalam diagnosis kerusakan.
C18: 15 | D18: Ember (10–15 L) | E18: 1 pcs | F18: Penampung air bilasan | H18: Consumable (Bahan Habis Pakai) | I18: 15 | J18: Chemical Coil Cleaner Heavy Duty | K18: ±1–2 L/unit | L18: Pembersih coil besar
B19: Consumable (Bahan Habis Pakai) | C19: 16 | D19: Chemical Coil Cleaner | E19: ±0.5–1 L/unit | F19: Pembersih sirip evaporator | I19: 16 | J19: Air Bersih | K19: ±10–20 L/unit | L19: Bilasan coil & casing
C20: 17 | D20: Air Bersih | E20: ±5–10 L/unit | F20: Bilasan setelah chemical | I20: 17 | J20: Plastik | K20: 1 lembar besar | L20: Lindungi plafon & lantai
C21: 18 | D21: Plastik Pelindung Area | E21: 1 lembar | F21: Melindungi dinding/lantai | I21: 18 | J21: Freon (R410A / R32) | K21: secukupnya | L21: Tambah freon bila perlu
C22: 19 | D22: Isolasi Pipa | E22: secukupnya | F22: Penggantian bila bocor | I22: 19 | J22: Lap & Kanebo | K22: 2 pcs | L22: Pengering akhir
C23: 20 | D23: Grease / Oli Fan | F23: Perawatan ringan motor fan | I23: 20 | J23: Grease / Oli Fan | L23: Perawatan ringan motor fan
C24: 21 | D24: Freon (R22 / R32 / R410A) | E24: secukupnya | F24: Refill jika tekanan kurang | H24: APD (Alat Pelindung Diri) | I24: 21 | J24: Sarung Tangan Karet Tahan Panas | K24: 1 pasang | L24: Lindungi tangan dari steam
B25: APD (Alat Pelindung Diri) | C25: 22 | D25: Sarung Tangan Karet | E25: 1 pasang | F25: Lindungi tangan dari chemical | I25: 22 | J25: Sepatu Safety Non-slip | K25: 1 pasang | L25: Aman di area basah
C26: 23 | D26: Helm Safety | E26: 1 pcs | F26: Wajib jika di plafon tinggi | I26: 23 | J26: Helm Safety | K26: 1 pcs | L26: Wajib jika di plafon tinggi
C27: 24 | D27: Sepatu Non-slip | E27: 1 pasang | F27: Cegah terpeleset

Sheet TOOLS AC Split
B3: Nama | C3: Peralatan Cleaning Service
B4: Area Layanan | C4: -
B5: Jenis Job Supply | C5: Maintenance AC Split
B8: Jenis Produk | C8: Total Price
B9: Tools | C9: =I43 -> 639159.21
B10: Consumable | C10: =I57 -> 521090
B11: Alat Pelindung Diri (APD) | C11: =I66 -> 153070.29
B12: Total Price | C12: =SUM(C9:C11) -> 1313319.5
B14: Asumsi Kerja | C14: Jumlah | D14: Keterangan
B15: Jumlah Petugas | C15: 3 | D15: Orang
B16: Jam Kerja | C16: 8 | D16: Jam
B20: TOOLS MAINTENANCE AC SPLIT
B21: Nama Item | C21: Spesifikasi | D21: Merk | E21: Kuantitas | G21: Unit Price | H21: Depresiasi | I21: Total Price
E22: Jumlah | F22: Satuan
B23: Pompa Steam | C23: - | D23: - | E23: 1 | F23: Pcs | G23: 1016500 | H23: 12 | I23: =(G23*E23)/H23 -> 84708.333
B24: Selang Pompa Steam AC | C24: - | D24: - | E24: 1 | F24: Pcs | G24: 417300 | H24: 24 | I24: =(G24*E24)/H24 -> 17387.5
B25: Plastik Service AC | C25: - | D25: - | E25: 1 | F25: Pcs | G25: 66340 | H25: 1 | I25: =(G25*E25)/H25 -> 66340
B26: Tangga Lipat | C26: - | D26: - | E26: 1 | F26: Pcs | G26: 1947400 | H26: 24 | I26: =(G26*E26)/H26 -> 81141.667
B27: Mesin Vacuum AC | C27: - | D27: - | E27: 1 | F27: Pcs | G27: 1284000 | H27: 12 | I27: =(G27*E27)/H27 -> 107000
B28: Manifold | C28: - | D28: - | E28: 1 | F28: Pcs | G28: 214000 | H28: 12 | I28: =(G28*E28)/H28 -> 17833.333
B29: Manifold | C29: - | D29: - | E29: 1 | F29: Pcs | G29: 695500 | H29: 12 | I29: =(G29*E29)/H29 -> 57958.333
B30: Manifold | C30: - | D30: - | E30: 1 | F30: Pcs | G30: 310300 | H30: 12 | I30: =(G30*E30)/H30 -> 25858.333
B31: Thermogun | C31: - | D31: - | E31: 1 | F31: Pcs | G31: 177620 | H31: 12 | I31: =(G31*E31)/H31 -> 14801.667
B32: Obeng Min (-) | C32: - | D32: - | E32: 1 | F32: Pcs | G32: 43870 | H32: 24 | I32: =(G32*E32)/H32 -> 1827.9167
B33: Obeng Plus (+) | C33: - | D33: - | E33: 1 | F33: Pcs | G33: 47080 | H33: 24 | I33: =(G33*E33)/H33 -> 1961.6667
B34: Kanebo | C34: - | D34: - | E34: 2 | F34: Pcs | G34: 16050 | H34: 2 | I34: =(G34*E34)/H34 -> 16050
... B42: Clamp Meter | C42: - | D42: - | E42: 1 | F42: Pcs | G42: 2275248 | H42: 24 | I42: =(G42*E42)/H42 -> 94802
B43: Total Harga | I43: =SUM(I23:I42) -> 639159.21
B46: CONSUMABLE MAINTENANCE AC SPLIT
B47: Nama Item | C47: Spesifikasi | D47: Merk | E47: Kuantitas | G47: Unit Price | H47: Depresiasi | I47: Total Price
E48: Jumlah | F48: Satuan
B49: Chemical Coil Cleaner | C49: - | D49: - | E49: 1 | F49: Ltr | G49: 214000 | H49: 12 | I49: =(G49*E49)/H49 -> 17833.333
B50: Air Bersih | C50: - | D50: - | E50: 1 | F50: Ltr | G50: 0 | H50: 12 | I50: =(G50*E50)/H50 -> 0
B51: Plastik Pelindung Area | C51: Plastik Service AC | D51: - | E51: 1 | F51: Pcs | G51: 66340 | H51: 1 | I51: =(G51*E51)/H51 -> 66340
B52: Isolasi Pipa | C52: - | D52: - | E52: 1 | F52: secukupnya | G52: 0 | H52: 12 | I52: =(G52*E52)/H52 -> 0
B53: Grease / Oli Fan | C53: - | D53: - | E53: 1 | F53: Ltr | G53: 0 | H53: 12 | I53: =(G53*E53)/H53 -> 0
B54: Freon R22 | C54: - | D54: - | E54: 1 | F54: Pcs | G54: 1310750 | H54: 3 | I54: =(G54*E54)/H54 -> 436916.67
B55: Freon R41 | E55: 1 | F55: Pcs | G55: 1273300 | H55: 3 | I55: =(G55*E55)/H55 -> 424433.33
B56: Freon R32 | E56: 1 | F56: Pcs | G56: 1230500 | H56: 3 | I56: =(G56*E56)/H56 -> 410166.67
B57: Total Harga | I57: =SUM(I49:I54) -> 521090
...

Sheet Pricelist Split
B5: Parameter | C5: Nilai | D5: Keterangan | F5: Biaya (Tools+APD) | I5: Biaya (Consumable) | L5: Biaya (Tenaga Kerja)
B6: Banyak AC | C6: 1 | D6: Unit | F6: Jenis Produk | G6: Unit Price | I6: Jenis Produk | J6: Unit Price | L6: Item | M6: Unit Price
B7: Frekuensi | C7: 1 | D7: kali pembersihan | F7: Tools | G7: ='TOOLS AC Split'!C9 -> 639159.21 | I7: Consumable | J7: ='TOOLS AC Split'!C10 -> 521090 | L7: Gaji | M7: 80000
B8: Depresiasi | C8: 1 | D8: tahun (12 bulan) | F8: APD | G8: ='TOOLS AC Split'!C11 -> 153070.29 | I8: Total Price | J8: =J7 -> 521090 | L8: Transportasi | M8: 50000
B9: Target Jumlah Proyek per tahun | C9: 200 | D9: (1 minggu = 4) x 50 minggu | F9: Total Price | G9: =SUM(G7:G8) -> 792229.5 | L9: Total Price | M9: =SUM(M7:M8) -> 130000
B10: Biaya Tenaga Kerja per Kunjungan | C10: 80000
B11: Overhead & Transportasi | C11: 50000 | D11: Kunjungan | F11: Total Biaya Satuan
B12: Margin Keuntungan Target | C12: 0.3 | F12: Item | G12: Unit Price
B13: Asumsi Consumable | C13: 20 | F13: Tools + APD | G13: =G9 -> 792229.5
F14: Consumable | G14: =J8 -> 521090
B15: Parameter' | C15: Unit Price | F15: Tenaga Kerja | G15: =M9 -> 130000
B16: Cost per Unit | C16: =G16 -> 1443319.5 | F16: Total Biaya Dasar | G16: =SUM(G13:G15) -> 1443319.5
B17: Harga Jual per Unit | C17: =K19-H19 -> 432995.85
F18: Jumlah AC | G18: Satuan | H18: Unit Price | I18: Margin | J18: Keuntungan | K18: Unit Price + Margin
F19: 1 | G19: Unit | H19: =G16 -> 1443319.5 | I19: 0.3 | J19: 1 | K19: =H19*(J19+I19) -> 1876315.4
F20: 5 | G20: Unit | H20: =G16/F20 -> 288663.9 | I20: 0.3 | J20: 1 | K20: =H20*(J20+I20) -> 375263.07
F21: 10 | G21: Unit | H21: =G16/F21 -> 144331.95 | I21: 0.3 | J21: 1 | K21: =H21*(J21+I21) -> 187631.54
J22: 1 = 100% biaya pokok (modal awal)
F24: Perhitungan Biaya (Keuntungan)
F25: Total Biaya Dasar | G25: =G16 -> 1443319.5
F26: Keuntungan | G26: 1.3
F27: Total Pricelist (m) | G27: =G25*G26 -> 1876315.4

Sheet TOOLS AC Kaset
B3: Nama | C3: Peralatan Cleaning Service
B4: Area Layanan | C4: -
B5: Jenis Job Supply | C5: Maintenance AC Kaset
B8: Jenis Produk | C8: Total Price
B9: Tools | C9: =I45 -> 1037440.3
B10: Consumable | C10: =I58 -> 521090
B11: Alat Pelindung Diri (APD) | C11: =I67 -> 153070.29
B12: Total Price | C12: =SUM(C9:C11) -> 1711600.6
B14: Asumsi Kerja | C14: Jumlah | D14: Keterangan
B15: Jumlah Petugas | C15: 3 | D15: Orang
B16: Jam Kerja | C16: 8 | D16: Jam
B20: TOOLS MAINTENANCE AC KASET
B21: Nama Item | C21: Spesifikasi | D21: Merk | E21: Kuantitas | G21: Unit Price | H21: Depresiasi | I21: Total Price
E22: Jumlah | F22: Satuan
B23: Pompa Steam Tekanan Tinggi | C23: - | D23: - | E23: 1 | F23: Pcs | G23: 1016500 | H23: 12 | I23: =(G23*E23)/H23 -> 84708.333
B24: Selang Pompa Steam AC | C24: 10-15 m | D24: - | E24: 1 | F24: Pcs | G24: 417300 | H24: 24 | I24: =(G24*E24)/H24 -> 17387.5
B25: Plastik | C25: - | D25: - | E25: 1 | F25: Pcs | G25: 66340 | H25: 1 | I25: =(G25*E25)/H25 -> 66340
B26: Terpal | C26: - | D26: - | E26: 1 | F26: Pcs | G26: 393760 | H26: 12 | I26: =(G26*E26)/H26 -> 32813.333
B27: Tangga Alumunium 1,5 m | C27: 1,5 m | D27: - | E27: 1 | F27: Pcs | G27: 1186512 | H27: 24 | I27: =(G27*E27)/H27 -> 49438
B28: Tangga Alumunium 2 m | C28: 2 m | D28: - | E28: 1 | F28: Pcs | G28: 2994930 | H28: 24 | I28: =(G28*E28)/H28 -> 124788.75
B29: Mesin Vacuum AC | C29: - | D29: - | E29: 1 | F29: Pcs | G29: 1284000 | H29: 12 | I29: =(G29*E29)/H29 -> 107000
B30: Manifold | C30: - | D30: - | E30: 1 | F30: Pcs | G30: 214000 | H30: 12 | I30: =(G30*E30)/H30 -> 17833.333
B31: Manifold | C31: - | D31: - | E31: 1 | F31: Pcs | G31: 695500 | H31: 12 | I31: =(G31*E31)/H31 -> 57958.333
B32: Manifold | C32: - | D32: - | E32: 1 | F32: Pcs | G32: 310300 | H32: 12 | I32: =(G32*E32)/H32 -> 25858.333
B33: Thermogun | C33: - | D33: - | E33: 1 | F33: Pcs | G33: 177620 | H33: 12 | I33: =(G33*E33)/H33 -> 14801.667
B34: Obeng Set Lengkap | C34: - | D34: - | E34: 1 | F34: Set | G34: 201160 | H34: 24 | I34: =(G34*E34)/H34 -> 8381.6667
... B44: Clamp Meter | C44: - | D44: - | E44: 1 | F44: Pcs | G44: 2275248 | H44: 24 | I44: =(G44*E44)/H44 -> 94802
B45: Total Harga | I45: =SUM(I23:I44) -> 1037440.3
B47: CONSUMABLE MAINTENANCE AC SPLIT
B48: Nama Item | C48: Spesifikasi | D48: Merk | E48: Kuantitas | G48: Unit Price | H48: Depresiasi | I48: Total Price
E49: Jumlah | F49: Satuan
B50: Chemical Coil Cleaner | C50: - | D50: - | E50: 1 | F50: Ltr | G50: 214000 | H50: 12 | I50: =(G50*E50)/H50 -> 17833.333
B51: Air Bersih | C51: - | D51: - | E51: 1 | F51: Ltr | G51: 0 | H51: 12 | I51: =(G51*E51)/H51 -> 0
B52: Plastik Pelindung Area | C52: Plastik Service AC | D52: - | E52: 1 | F52: Pcs | G52: 66340 | H52: 1 | I52: =(G52*E52)/H52 -> 66340
B53: Isolasi Pipa | C53: - | D53: - | E53: 1 | F53: secukupnya | G53: 0 | H53: 12 | I53: =(G53*E53)/H53 -> 0
B54: Grease / Oli Fan | C54: - | D54: - | E54: 1 | F54: Ltr | G54: 0 | H54: 12 | I54: =(G54*E54)/H54 -> 0
B55: Freon R22 | C55: - | D55: - | E55: 1 | F55: Pcs | G55: 1310750 | H55: 3 | I55: =(G55*E55)/H55 -> 436916.67
B56: Freon R41 | E56: 1 | F56: Pcs | G56: 1273300 | H56: 3 | I56: =(G56*E56)/H56 -> 424433.33
B57: Freon R32 | E57: 1 | F57: Pcs | G57: 1230500 | H57: 3 | I57: =(G57*E57)/H57 -> 410166.67
B58: Total Harga | I58: =SUM(I50:I55) -> 521090
...

Sheet Pricelist Kaset
B5: Parameter | C5: Nilai | D5: Keterangan | F5: Biaya (Tools+APD) | I5: Biaya (Consumable) | L5: Biaya (Tenaga Kerja)
B6: Banyak AC | C6: 1 | D6: Unit | F6: Jenis Produk | G6: Unit Price | I6: Jenis Produk | J6: Unit Price | L6: Item | M6: Unit Price
B7: Frekuensi | C7: 1 | D7: kali pembersihan | F7: Tools | G7: ='TOOLS AC Kaset'!C9 -> 1037440.3 | I7: Consumable | J7: ='TOOLS AC Kaset'!C10 -> 521090 | L7: Gaji | M7: 80000
B8: Depresiasi | C8: 1 | D8: tahun (12 bulan) | F8: APD | G8: ='TOOLS AC Kaset'!C11 -> 153070.29 | I8: Total Price | J8: =J7 -> 521090 | L8: Transportasi | M8: 50000
B9: Target Jumlah Proyek per tahun | C9: 200 | D9: (1 minggu = 4) x 50 minggu | F9: Total Price | G9: =SUM(G7:G8) -> 1190510.6 | L9: Total Price | M9: =SUM(M7:M8) -> 130000
B10: Biaya Tenaga Kerja per Kunjungan | C10: 80000
B11: Overhead & Transportasi | C11: 50000 | D11: Kunjungan | F11: Total Biaya Satuan
B12: Margin Keuntungan Target | C12: 0.3 | F12: Item | G12: Unit Price
B13: Asumsi Consumable | C13: 20 | F13: Tools + APD | G13: =G9 -> 1190510.6
F14: Consumable | G14: =J8 -> 521090
B15: Parameter' | C15: Unit Price | F15: Tenaga Kerja | G15: =M9 -> 130000
B16: Cost per Unit | C16: =G16 -> 1841600.6 | F16: Total Biaya Dasar | G16: =SUM(G13:G15) -> 1841600.6
B17: Harga Jual per Unit | C17: =K19-H19 -> 552480.19
F18: Jumlah AC | G18: Satuan | H18: Unit Price | I18: Margin | J18: Keuntungan | K18: Unit Price + Margin
F19: 1 | G19: Unit | H19: =G16 -> 1841600.6 | I19: 0.3 | J19: 1 | K19: =H19*(J19+I19) -> 2394080.8
F20: 5 | G20: Unit | H20: =G16/F20 -> 368320.12 | I20: 0.3 | J20: 1 | K20: =H20*(J20+I20) -> 478816.16
F21: 10 | G21: Unit | H21: =G16/F21 -> 184160.06 | I21: 0.3 | J21: 1 | K21: =H21*(J21+I21) -> 239408.08
B22: Jadi angka Rp 4.650/m² itu termasuk harga dasar internal, masih di bawah kisaran pasar, cocok dijadikan harga pokok produksi (HPP) sebelum markup margin | J22: 1 = 100% biaya pokok (modal awal)
F24: Perhitungan Biaya (Keuntungan)
F25: Total Biaya Dasar | G25: =G16 -> 1841600.6
F26: Keuntungan | G26: 1.3
F27: Total Pricelist (m) | G27: =G25*G26 -> 2394080.8
